Workbook

Sheet 说明
A1: Hibi · 宜忌词典
A3: 这是什么 | B3: 每天的宜、忌由真实黄历算出（lunar-javascript，2026–2030 五年里一共出现 114 个老词）。面板上不显示老词，只显示你在「词典」里为它写的现代版。
A4: 方向 | B4: A day for = 照顾自己：休息、喝水、运动、看云、联系家人和朋友。 Not for today = 拼命、激进、功利，或为还没发生的事焦虑。
A5: 你要改的 | B5: 只改「词典」里黄色的四列（E–H）：中文 4 个字，英文尽量不超过 26 个字符。I 列会自动提示字数问题。
A6: 留空 | B6: 把某个格子清空 = 这个老词在那一侧永远不会被选中。
A7: 灰色格子 | B7: 这个老词从不出现在那一侧（例如「解除」从来不是忌），不用填。
A8: 次数 | B8: C、D 列是五年里出现的天数。次数越高越常被选到，建议先改排在前面的。
A9: 特殊日 | B9: 诸事不宜：当天的宜只有这一条（约每年 3 天）。无：当天没有忌（约每年 11 天）。馀事勿取：只是修饰语，不会被选中。
A10: 怎么选 | B10: 每天从当天真实的宜、忌列表里，各挑一个有现代版的老词；同一日期在任何设备上结果都一样，并尽量避开过去一周出现过的。
A11: 预览 | B11: 「预览」页是从 2026-10-16 起的 30 天。挑中的老词是固定的，现代版会跟着你在「词典」里的修改自动更新。
A12: 示例 | B12: 第一行「安葬」：古义是埋葬逝者，宜写成「放下旧事 / Let old things rest」，忌写成「埋头苦干 / Bury yourself in work」。

Sheet 词典
A1: 老词 | B1: 古义 | C1: 宜·次数 | D1: 忌·次数 | E1: A day for · 中文 | F1: A day for · English | G1: Not for today · 中文 | H1: Not for today · English | I1: 检查
A2: 安葬 | B2: 埋葬逝者 | C2: 612 | D2: 765 | E2: 放下旧事 | F2: Let old things rest | G2: 埋头苦干 | H2: Bury yourself in work | I2: =TRIM(IF(AND(E2<>"",LEN(E2)<>4),"宜不是4字 ","")&IF(AND(G2<>"",LEN(G2)<>4),"忌不是4字 ","")&IF(LEN(F2)>26,"宜英文偏长 ","")&IF(LEN(H2)>26,"忌英文偏长",""))
A3: 嫁娶 | B3: 结婚嫁娶 | C3: 633 | D3: 719 | E3: 拥抱家人 | F3: Hug your family | G3: 一口答应 | H3: Say yes to everything | I3: =TRIM(IF(AND(E3<>"",LEN(E3)<>4),"宜不是4字 ","")&IF(AND(G3<>"",LEN(G3)<>4),"忌不是4字 ","")&IF(LEN(F3)>26,"宜英文偏长 ","")&IF(LEN(H3)>26,"忌英文偏长",""))
A4: 祭祀 | B4: 祭拜祖先神明 | C4: 1212 | D4: 124 | E4: 打给爸妈 | F4: Call your parents | G4: 许愿暴富 | H4: Wish to get rich quick | I4: =TRIM(IF(AND(E4<>"",LEN(E4)<>4),"宜不是4字 ","")&IF(AND(G4<>"",LEN(G4)<>4),"忌不是4字 ","")&IF(LEN(F4)>26,"宜英文偏长 ","")&IF(LEN(H4)>26,"忌英文偏长",""))
A5: 入宅 | B5: 搬入新居 | C5: 474 | D5: 626 | E5: 窝在家里 | F5: Stay in and nest | G5: 与人攀比 | H5: Compare yourself | I5: =TRIM(IF(AND(E5<>"",LEN(E5)<>4),"宜不是4字 ","")&IF(AND(G5<>"",LEN(G5)<>4),"忌不是4字 ","")&IF(LEN(F5)>26,"宜英文偏长 ","")&IF(LEN(H5)>26,"忌英文偏长",""))
A6: 动土 | B6: 建房破土开工 | C6: 572 | D6: 440 | E6: 赤脚踩草 | F6: Walk barefoot on grass | G6: 大干一场 | H6: Go all in | I6: =TRIM(IF(AND(E6<>"",LEN(E6)<>4),"宜不是4字 ","")&IF(AND(G6<>"",LEN(G6)<>4),"忌不是4字 ","")&IF(LEN(F6)>26,"宜英文偏长 ","")&IF(LEN(H6)>26,"忌英文偏长",""))
A7: 开市 | B7: 店铺开张营业 | C7: 396 | D7: 574 | E7: 慢慢开工 | F7: Ease into the day | G7: 冲刺业绩 | H7: Chase your targets | I7: =TRIM(IF(AND(E7<>"",LEN(E7)<>4),"宜不是4字 ","")&IF(AND(G7<>"",LEN(G7)<>4),"忌不是4字 ","")&IF(LEN(F7)>26,"宜英文偏长 ","")&IF(LEN(H7)>26,"忌英文偏长",""))
A8: 破土 | B8: 为墓地挖土 | C8: 523 | D8: 401 | E8: 种点花草 | F8: Plant something | G8: 另起炉灶 | H8: Start yet another project | I8: =TRIM(IF(AND(E8<>"",LEN(E8)<>4),"宜不是4字 ","")&IF(AND(G8<>"",LEN(G8)<>4),"忌不是4字 ","")&IF(LEN(F8)>26,"宜英文偏长 ","")&IF(LEN(H8)>26,"忌英文偏长",""))
A9: 出行 | B9: 外出远行 | C9: 608 | D9: 215 | E9: 出门走走 | F9: Take a walk | G9: 赶来赶去 | H9: Rush from place to place | I9: =TRIM(IF(AND(E9<>"",LEN(E9)<>4),"宜不是4字 ","")&IF(AND(G9<>"",LEN(G9)<>4),"忌不是4字 ","")&IF(LEN(F9)>26,"宜英文偏长 ","")&IF(LEN(H9)>26,"忌英文偏长",""))
A10: 祈福 | B10: 祈求神明降福 | C10: 596 | D10: 195 | E10: 许个心愿 | F10: Make a small wish | G10: 患得患失 | H10: Fret over gains and losses | I10: =TRIM(IF(AND(E10<>"",LEN(E10)<>4),"宜不是4字 ","")&IF(AND(G10<>"",LEN(G10)<>4),"忌不是4字 ","")&IF(LEN(F10)>26,"宜英文偏长 ","")&IF(LEN(H10)>26,"忌英文偏长",""))
A11: 移徙 | B11: 搬家迁居 | C11: 524 | D11: 235 | E11: 起身走动 | F11: Get up and move | G11: 跳槽加薪 | H11: Job-hop for a raise | I11: =TRIM(IF(AND(E11<>"",LEN(E11)<>4),"宜不是4字 ","")&IF(AND(G11<>"",LEN(G11)<>4),"忌不是4字 ","")&IF(LEN(F11)>26,"宜英文偏长 ","")&IF(LEN(H11)>26,"忌英文偏长",""))
A12: 安床 | B12: 安放床铺 | C12: 473 | D12: 236 | E12: 早早入睡 | F12: Sleep early | G12: 熬夜加班 | H12: Stay up working | I12: =TRIM(IF(AND(E12<>"",LEN(E12)<>4),"宜不是4字 ","")&IF(AND(G12<>"",LEN(G12)<>4),"忌不是4字 ","")&IF(LEN(F12)>26,"宜英文偏长 ","")&IF(LEN(H12)>26,"忌英文偏长",""))
A13: 开光 | B13: 神像开光 | C13: 504 | D13: 205 | E13: 看看云朵 | F13: Watch the clouds | G13: 死盯数据 | H13: Obsess over metrics | I13: =TRIM(IF(AND(E13<>"",LEN(E13)<>4),"宜不是4字 ","")&IF(AND(G13<>"",LEN(G13)<>4),"忌不是4字 ","")&IF(LEN(F13)>26,"宜英文偏长 ","")&IF(LEN(H13)>26,"忌英文偏长",""))
... A20: 出火 | B20: 迁移神位香火 | C20: 329 | D20: 137 | E20: 晒晒太阳 | F20: Soak up the sun | G20: 火力全开 | H20: Go full throttle | I20: =TRIM(IF(AND(E20<>"",LEN(E20)<>4),"宜不是4字 ","")&IF(AND(G20<>"",LEN(G20)<>4),"忌不是4字 ","")&IF(LEN(F20)>26,"宜英文偏长 ","")&IF(LEN(H20)>26,"忌英文偏长",""))
A21: 解除 | B21: 扫舍、解除灾厄 | C21: 449 | D21: 0 | E21: 解开心结 | F21: Let something go | I21: =TRIM(IF(AND(E21<>"",LEN(E21)<>4),"宜不是4字 ","")&IF(AND(G21<>"",LEN(G21)<>4),"忌不是4字 ","")&IF(LEN(F21)>26,"宜英文偏长 ","")&IF(LEN(H21)>26,"忌英文偏长",""))
A22: 会亲友 | B22: 拜访亲友 | C22: 410 | D22: 27 | E22: 与友闲聊 | F22: Chat with a friend | G22: 只谈生意 | H22: Talk only business | I22: =TRIM(IF(AND(E22<>"",LEN(E22)<>4),"宜不是4字 ","")&IF(AND(G22<>"",LEN(G22)<>4),"忌不是4字 ","")&IF(LEN(F22)>26,"宜英文偏长 ","")&IF(LEN(H22)>26,"忌英文偏长",""))
A23: 栽种 | B23: 种植 | C23: 301 | D23: 136 | E23: 给花浇水 | F23: Water the plants | G23: 揠苗助长 | H23: Force things to grow | I23: =TRIM(IF(AND(E23<>"",LEN(E23)<>4),"宜不是4字 ","")&IF(AND(G23<>"",LEN(G23)<>4),"忌不是4字 ","")&IF(LEN(F23)>26,"宜英文偏长 ","")&IF(LEN(H23)>26,"忌英文偏长",""))
A24: 交易 | B24: 买卖交易 | C24: 376 | D24: 56 | E24: 互道近况 | F24: Swap news with someone | G24: 斤斤计较 | H24: Count every penny | I24: =TRIM(IF(AND(E24<>"",LEN(E24)<>4),"宜不是4字 ","")&IF(AND(G24<>"",LEN(G24)<>4),"忌不是4字 ","")&IF(LEN(F24)>26,"宜英文偏长 ","")&IF(LEN(H24)>26,"忌英文偏长",""))
A25: 立券 | B25: 订立契约 | C25: 407 | D25: 23 | E25: 提笔写字 | F25: Write by hand | G25: 把话说满 | H25: Overpromise | I25: =TRIM(IF(AND(E25<>"",LEN(E25)<>4),"宜不是4字 ","")&IF(AND(G25<>"",LEN(G25)<>4),"忌不是4字 ","")&IF(LEN(F25)>26,"宜英文偏长 ","")&IF(LEN(H25)>26,"忌英文偏长",""))
A26: 馀事勿取 | B26: 其余事都不宜（修饰语，不单独显示） | C26: 425 | D26: 5 | I26: =TRIM(IF(AND(E26<>"",LEN(E26)<>4),"宜不是4字 ","")&IF(AND(G26<>"",LEN(G26)<>4),"忌不是4字 ","")&IF(LEN(F26)>26,"宜英文偏长 ","")&IF(LEN(H26)>26,"忌英文偏长",""))
A27: 安门 | B27: 安装大门 | C27: 192 | D27: 187 | E27: 关门休息 | F27: Close the door and rest | G27: 来者不拒 | H27: Take on every request | I27: =TRIM(IF(AND(E27<>"",LEN(E27)<>4),"宜不是4字 ","")&IF(AND(G27<>"",LEN(G27)<>4),"忌不是4字 ","")&IF(LEN(F27)>26,"宜英文偏长 ","")&IF(LEN(H27)>26,"忌英文偏长",""))
A28: 纳畜 | B28: 买入家畜 | C28: 311 | D28: 64 | E28: 撸猫撸狗 | F28: Pet a cat or a dog | G28: 囤货抢购 | H28: Panic-buy and hoard | I28: =TRIM(IF(AND(E28<>"",LEN(E28)<>4),"宜不是4字 ","")&IF(AND(G28<>"",LEN(G28)<>4),"忌不是4字 ","")&IF(LEN(F28)>26,"宜英文偏长 ","")&IF(LEN(H28)>26,"忌英文偏长",""))
A29: 斋醮 | B29: 设坛祭祷 | C29: 241 | D29: 127 | E29: 发呆片刻 | F29: Stare into space | G29: 多线并行 | H29: Multitask everything | I29: =TRIM(IF(AND(E29<>"",LEN(E29)<>4),"宜不是4字 ","")&IF(AND(G29<>"",LEN(G29)<>4),"忌不是4字 ","")&IF(LEN(F29)>26,"宜英文偏长 ","")&IF(LEN(H29)>26,"忌英文偏长",""))
A30: 求嗣 | B30: 祈求子嗣 | C30: 364 | D30: 0 | E30: 找回童心 | F30: Play like a child | I30: =TRIM(IF(AND(E30<>"",LEN(E30)<>4),"宜不是4字 ","")&IF(AND(G30<>"",LEN(G30)<>4),"忌不是4字 ","")&IF(LEN(F30)>26,"宜英文偏长 ","")&IF(LEN(H30)>26,"忌英文偏长",""))
A31: 移柩 | B31: 移动灵柩 | C31: 349 | D31: 3 | E31: 换个姿势 | F31: Change your posture | G31: 连轴运转 | H31: Run nonstop | I31: =TRIM(IF(AND(E31<>"",LEN(E31)<>4),"宜不是4字 ","")&IF(AND(G31<>"",LEN(G31)<>4),"忌不是4字 ","")&IF(LEN(F31)>26,"宜英文偏长 ","")&IF(LEN(H31)>26,"忌英文偏长",""))
A32: 启钻 | B32: 开坟迁葬 | C32: 341 | D32: 10 | E32: 翻翻旧照 | F32: Look at old photos | G32: 翻看旧账 | H32: Dwell on the past | I32: =TRIM(IF(AND(E32<>"",LEN(E32)<>4),"宜不是4字 ","")&IF(AND(G32<>"",LEN(G32)<>4),"忌不是4字 ","")&IF(LEN(F32)>26,"宜英文偏长 ","")&IF(LEN(H32)>26,"忌英文偏长",""))
A33: 拆卸 | B33: 拆除旧屋 | C33: 333 | D33: 0 | E33: 卸下包袱 | F33: Put your burdens down | I33: =TRIM(IF(AND(E33<>"",LEN(E33)<>4),"宜不是4字 ","")&IF(AND(G33<>"",LEN(G33)<>4),"忌不是4字 ","")&IF(LEN(F33)>26,"宜英文偏长 ","")&IF(LEN(H33)>26,"忌英文偏长",""))
A34: 成服 | B34: 穿上丧服 | C34: 320 | D34: 12 | E34: 穿件软衣 | F34: Wear something soft | G34: 全副武装 | H34: Armor up for battle | I34: =TRIM(IF(AND(E34<>"",LEN(E34)<>4),"宜不是4字 ","")&IF(AND(G34<>"",LEN(G34)<>4),"忌不是4字 ","")&IF(LEN(F34)>26,"宜英文偏长 ","")&IF(LEN(H34)>26,"忌英文偏长",""))
A35: 除服 | B35: 脱下丧服 | C35: 324 | D35: 7 | E35: 换上睡衣 | F35: Change into pajamas | G35: 带病上班 | H35: Work while sick | I35: =TRIM(IF(AND(E35<>"",LEN(E35)<>4),"宜不是4字 ","")&IF(AND(G35<>"",LEN(G35)<>4),"忌不是4字 ","")&IF(LEN(F35)>26,"宜英文偏长 ","")&IF(LEN(H35)>26,"忌英文偏长",""))
A36: 起基 | B36: 打地基 | C36: 319 | D36: 11 | E36: 吃好早餐 | F36: Eat a proper breakfast | G36: 规划十年 | H36: Plan the next ten years | I36: =TRIM(IF(AND(E36<>"",LEN(E36)<>4),"宜不是4字 ","")&IF(AND(G36<>"",LEN(G36)<>4),"忌不是4字 ","")&IF(LEN(F36)>26,"宜英文偏长 ","")&IF(LEN(H36)>26,"忌英文偏长",""))
A37: 掘井 | B37: 挖井 | C37: 86 | D37: 244 | E37: 多喝点水 | F37: Drink more water | G37: 钻牛角尖 | H37: Overthink it | I37: =TRIM(IF(AND(E37<>"",LEN(E37)<>4),"宜不是4字 ","")&IF(AND(G37<>"",LEN(G37)<>4),"忌不是4字 ","")&IF(LEN(F37)>26,"宜英文偏长 ","")&IF(LEN(H37)>26,"忌英文偏长",""))
A38: 沐浴 | B38: 斋戒沐浴 | C38: 321 | D38: 0 | E38: 泡个热澡 | F38: Take a warm bath | I38: =TRIM(IF(AND(E38<>"",LEN(E38)<>4),"宜不是4字 ","")&IF(AND(G38<>"",LEN(G38)<>4),"忌不是4字 ","")&IF(LEN(F38)>26,"宜英文偏长 ","")&IF(LEN(H38)>26,"忌英文偏长",""))
A39: 盖屋 | B39: 盖房子 | C39: 173 | D39: 147 | E39: 窝进被窝 | F39: Burrow under the covers | G39: 层层加码 | H39: Keep raising the bar | I39: =TRIM(IF(AND(E39<>"",LEN(E39)<>4),"宜不是4字 ","")&IF(AND(G39<>"",LEN(G39)<>4),"忌不是4字 ","")&IF(LEN(F39)>26,"宜英文偏长 ","")&IF(LEN(H39)>26,"忌英文偏长",""))
A40: 冠笄 | B40: 成年礼 | C40: 305 | D40: 7 | E40: 夸夸自己 | F40: Praise yourself | G40: 急于证明 | H40: Rush to prove yourself | I40: =TRIM(IF(AND(E40<>"",LEN(E40)<>4),"宜不是4字 ","")&IF(AND(G40<>"",LEN(G40)<>4),"忌不是4字 ","")&IF(LEN(F40)>26,"宜英文偏长 ","")&IF(LEN(H40)>26,"忌英文偏长",""))
A41: 纳财 | B41: 收进钱财 | C41: 292 | D41: 18 | E41: 收下好意 | F41: Accept a kindness | G41: 见钱眼开 | H41: Chase every dollar | I41: =TRIM(IF(AND(E41<>"",LEN(E41)<>4),"宜不是4字 ","")&IF(AND(G41<>"",LEN(G41)<>4),"忌不是4字 ","")&IF(LEN(F41)>26,"宜英文偏长 ","")&IF(LEN(H41)>26,"忌英文偏长",""))
A42: 伐木 | B42: 砍伐树木 | C42: 121 | D42: 159 | E42: 看看树叶 | F42: Look at the trees | G42: 牺牲睡眠 | H42: Trade sleep for work | I42: =TRIM(IF(AND(E42<>"",LEN(E42)<>4),"宜不是4字 ","")&IF(AND(G42<>"",LEN(G42)<>4),"忌不是4字 ","")&IF(LEN(F42)>26,"宜英文偏长 ","")&IF(LEN(H42)>26,"忌英文偏长",""))
A43: 牧养 | B43: 放牧饲养 | C43: 241 | D43: 13 | E43: 慢慢吃饭 | F43: Eat slowly | G43: 压榨自己 | H43: Squeeze yourself dry | I43: =TRIM(IF(AND(E43<>"",LEN(E43)<>4),"宜不是4字 ","")&IF(AND(G43<>"",LEN(G43)<>4),"忌不是4字 ","")&IF(LEN(F43)>26,"宜英文偏长 ","")&IF(LEN(H43)>26,"忌英文偏长",""))
A44: 进人口 | B44: 添丁、收养或雇人 | C44: 226 | D44: 26 | E44: 认识新友 | F44: Make a new friend | G44: 招兵买马 | H44: Scale up fast | I44: =TRIM(IF(AND(E44<>"",LEN(E44)<>4),"宜不是4字 ","")&IF(AND(G44<>"",LEN(G44)<>4),"忌不是4字 ","")&IF(LEN(F44)>26,"宜英文偏长 ","")&IF(LEN(H44)>26,"忌英文偏长",""))
A45: 治病 | B45: 求医治病 | C45: 185 | D45: 55 | E45: 照顾身体 | F45: Look after your body | G45: 小病硬扛 | H45: Ignore your aches | I45: =TRIM(IF(AND(E45<>"",LEN(E45)<>4),"宜不是4字 ","")&IF(AND(G45<>"",LEN(G45)<>4),"忌不是4字 ","")&IF(LEN(F45)>26,"宜英文偏长 ","")&IF(LEN(H45)>26,"忌英文偏长",""))
A46: 行丧 | B46: 办理丧事 | C46: 0 | D46: 225 | G46: 自我内耗 | H46: Wear yourself down | I46: =TRIM(IF(AND(E46<>"",LEN(E46)<>4),"宜不是4字 ","")&IF(AND(G46<>"",LEN(G46)<>4),"忌不是4字 ","")&IF(LEN(F46)>26,"宜英文偏长 ","")&IF(LEN(H46)>26,"忌英文偏长",""))
...

Sheet 预览
A1: 日期 | B1: 星期 | C1: 农历 | D1: 宜·老词 | E1: A day for · 中文 | F1: A day for · English | G1: 忌·老词 | H1: Not for today · 中文 | I1: Not for today · English
A2: 46311 | B2: ="周"&CHOOSE(WEEKDAY(A2),"日","一","二","三","四","五","六") -> 周五 | C2: 九月初七 | D2: 合脊 | E2: =IFERROR(INDEX(词典!$E$2:$E$115,MATCH(D2,词典!$A$2:$A$115,0)),"") -> 静听雨声 | F2: =IFERROR(INDEX(词典!$F$2:$F$115,MATCH(D2,词典!$A$2:$A$115,0)),"") -> Listen to the rain | G2: 安葬 | H2: =IFERROR(INDEX(词典!$G$2:$G$115,MATCH(G2,词典!$A$2:$A$115,0)),"") -> 埋头苦干 | I2: =IFERROR(INDEX(词典!$H$2:$H$115,MATCH(G2,词典!$A$2:$A$115,0)),"") -> Bury yourself in work
A3: 46312 | B3: ="周"&CHOOSE(WEEKDAY(A3),"日","一","二","三","四","五","六") -> 周六 | C3: 九月初八 | D3: 理发 | E3: =IFERROR(INDEX(词典!$E$2:$E$115,MATCH(D3,词典!$A$2:$A$115,0)),"") -> 剪个头发 | F3: =IFERROR(INDEX(词典!$F$2:$F$115,MATCH(D3,词典!$A$2:$A$115,0)),"") -> Get a haircut | G3: 入宅 | H3: =IFERROR(INDEX(词典!$G$2:$G$115,MATCH(G3,词典!$A$2:$A$115,0)),"") -> 与人攀比 | I3: =IFERROR(INDEX(词典!$H$2:$H$115,MATCH(G3,词典!$A$2:$A$115,0)),"") -> Compare yourself
A4: 46313 | B4: ="周"&CHOOSE(WEEKDAY(A4),"日","一","二","三","四","五","六") -> 周日 | C4: 九月初九 | D4: 造畜稠 | E4: =IFERROR(INDEX(词典!$E$2:$E$115,MATCH(D4,词典!$A$2:$A$115,0)),"") -> 布置小窝 | F4: =IFERROR(INDEX(词典!$F$2:$F$115,MATCH(D4,词典!$A$2:$A$115,0)),"") -> Make your corner cozy | G4: 嫁娶 | H4: =IFERROR(INDEX(词典!$G$2:$G$115,MATCH(G4,词典!$A$2:$A$115,0)),"") -> 一口答应 | I4: =IFERROR(INDEX(词典!$H$2:$H$115,MATCH(G4,词典!$A$2:$A$115,0)),"") -> Say yes to everything
A5: 46314 | B5: ="周"&CHOOSE(WEEKDAY(A5),"日","一","二","三","四","五","六") -> 周一 | C5: 九月初十 | D5: 破土 | E5: =IFERROR(INDEX(词典!$E$2:$E$115,MATCH(D5,词典!$A$2:$A$115,0)),"") -> 种点花草 | F5: =IFERROR(INDEX(词典!$F$2:$F$115,MATCH(D5,词典!$A$2:$A$115,0)),"") -> Plant something | G5: 置产 | H5: =IFERROR(INDEX(词典!$G$2:$G$115,MATCH(G5,词典!$A$2:$A$115,0)),"") -> 贪多求快 | I5: =IFERROR(INDEX(词典!$H$2:$H$115,MATCH(G5,词典!$A$2:$A$115,0)),"") -> Rush for more
A6: 46315 | B6: ="周"&CHOOSE(WEEKDAY(A6),"日","一","二","三","四","五","六") -> 周二 | C6: 九月十一 | D6: 祈福 | E6: =IFERROR(INDEX(词典!$E$2:$E$115,MATCH(D6,词典!$A$2:$A$115,0)),"") -> 许个心愿 | F6: =IFERROR(INDEX(词典!$F$2:$F$115,MATCH(D6,词典!$A$2:$A$115,0)),"") -> Make a small wish | G6: 移徙 | H6: =IFERROR(INDEX(词典!$G$2:$G$115,MATCH(G6,词典!$A$2:$A$115,0)),"") -> 跳槽加薪 | I6: =IFERROR(INDEX(词典!$H$2:$H$115,MATCH(G6,词典!$A$2:$A$115,0)),"") -> Job-hop for a raise
A7: 46316 | B7: ="周"&CHOOSE(WEEKDAY(A7),"日","一","二","三","四","五","六") -> 周三 | C7: 九月十二 | D7: 破屋 | E7: =IFERROR(INDEX(词典!$E$2:$E$115,MATCH(D7,词典!$A$2:$A$115,0)),"") -> 走出屋子 | F7: =IFERROR(INDEX(词典!$F$2:$F$115,MATCH(D7,词典!$A$2:$A$115,0)),"") -> Step outside | G7: 上梁 | H7: =IFERROR(INDEX(词典!$G$2:$G$115,MATCH(G7,词典!$A$2:$A$115,0)),"") -> 硬扛到底 | I7: =IFERROR(INDEX(词典!$H$2:$H$115,MATCH(G7,词典!$A$2:$A$115,0)),"") -> Tough it out alone
A8: 46317 | B8: ="周"&CHOOSE(WEEKDAY(A8),"日","一","二","三","四","五","六") -> 周四 | C8: 九月十三 | D8: 祭祀 | E8: =IFERROR(INDEX(词典!$E$2:$E$115,MATCH(D8,词典!$A$2:$A$115,0)),"") -> 打给爸妈 | F8: =IFERROR(INDEX(词典!$F$2:$F$115,MATCH(D8,词典!$A$2:$A$115,0)),"") -> Call your parents | G8: 安葬 | H8: =IFERROR(INDEX(词典!$G$2:$G$115,MATCH(G8,词典!$A$2:$A$115,0)),"") -> 埋头苦干 | I8: =IFERROR(INDEX(词典!$H$2:$H$115,MATCH(G8,词典!$A$2:$A$115,0)),"") -> Bury yourself in work
A9: 46318 | B9: ="周"&CHOOSE(WEEKDAY(A9),"日","一","二","三","四","五","六") -> 周五 | C9: 九月十四 | D9: 安葬 | E9: =IFERROR(INDEX(词典!$E$2:$E$115,MATCH(D9,词典!$A$2:$A$115,0)),"") -> 放下旧事 | F9: =IFERROR(INDEX(词典!$F$2:$F$115,MATCH(D9,词典!$A$2:$A$115,0)),"") -> Let old things rest | G9: 起基 | H9: =IFERROR(INDEX(词典!$G$2:$G$115,MATCH(G9,词典!$A$2:$A$115,0)),"") -> 规划十年 | I9: =IFERROR(INDEX(词典!$H$2:$H$115,MATCH(G9,词典!$A$2:$A$115,0)),"") -> Plan the next ten years
A10: 46319 | B10: ="周"&CHOOSE(WEEKDAY(A10),"日","一","二","三","四","五","六") -> 周六 | C10: 九月十五 | D10: 纳财 | E10: =IFERROR(INDEX(词典!$E$2:$E$115,MATCH(D10,词典!$A$2:$A$115,0)),"") -> 收下好意 | F10: =IFERROR(INDEX(词典!$F$2:$F$115,MATCH(D10,词典!$A$2:$A$115,0)),"") -> Accept a kindness | G10: 开池 | H10: =IFERROR(INDEX(词典!$G$2:$G$115,MATCH(G10,词典!$A$2:$A$115,0)),"") -> 竭泽而渔 | I10: =IFERROR(INDEX(词典!$H$2:$H$115,MATCH(G10,词典!$A$2:$A$115,0)),"") -> Drain the pond dry
A11: 46320 | B11: ="周"&CHOOSE(WEEKDAY(A11),"日","一","二","三","四","五","六") -> 周日 | C11: 九月十六 | D11: 立碑 | E11: =IFERROR(INDEX(词典!$E$2:$E$115,MATCH(D11,词典!$A$2:$A$115,0)),"") -> 记下美事 | F11: =IFERROR(INDEX(词典!$F$2:$F$115,MATCH(D11,词典!$A$2:$A$115,0)),"") -> Note a good moment | G11: 裁衣 | H11: =IFERROR(INDEX(词典!$G$2:$G$115,MATCH(G11,词典!$A$2:$A$115,0)),"") -> 冲动消费 | I11: =IFERROR(INDEX(词典!$H$2:$H$115,MATCH(G11,词典!$A$2:$A$115,0)),"") -> Shop on impulse
A12: 46321 | B12: ="周"&CHOOSE(WEEKDAY(A12),"日","一","二","三","四","五","六") -> 周一 | C12: 九月十七 | D12: 嫁娶 | E12: =IFERROR(INDEX(词典!$E$2:$E$115,MATCH(D12,词典!$A$2:$A$115,0)),"") -> 拥抱家人 | F12: =IFERROR(INDEX(词典!$F$2:$F$115,MATCH(D12,词典!$A$2:$A$115,0)),"") -> Hug your family | G12: 置产 | H12: =IFERROR(INDEX(词典!$G$2:$G$115,MATCH(G12,词典!$A$2:$A$115,0)),"") -> 贪多求快 | I12: =IFERROR(INDEX(词典!$H$2:$H$115,MATCH(G12,词典!$A$2:$A$115,0)),"") -> Rush for more
A13: 46322 | B13: ="周"&CHOOSE(WEEKDAY(A13),"日","一","二","三","四","五","六") -> 周二 | C13: 九月十八 | D13: 造畜稠 | E13: =IFERROR(INDEX(词典!$E$2:$E$115,MATCH(D13,词典!$A$2:$A$115,0)),"") -> 布置小窝 | F13: =IFERROR(INDEX(词典!$F$2:$F$115,MATCH(D13,词典!$A$2:$A$115,0)),"") -> Make your corner cozy | G13: 开渠 | H13: =IFERROR(INDEX(词典!$G$2:$G$115,MATCH(G13,词典!$A$2:$A$115,0)),"") -> 开个副业 | I13: =IFERROR(INDEX(词典!$H$2:$H$115,MATCH(G13,词典!$A$2:$A$115,0)),"") -> Start a side hustle
... A31: 46340 | B31: ="周"&CHOOSE(WEEKDAY(A31),"日","一","二","三","四","五","六") -> 周六 | C31: 十月初六 | D31: 进人口 | E31: =IFERROR(INDEX(词典!$E$2:$E$115,MATCH(D31,词典!$A$2:$A$115,0)),"") -> 认识新友 | F31: =IFERROR(INDEX(词典!$F$2:$F$115,MATCH(D31,词典!$A$2:$A$115,0)),"") -> Make a new friend | G31: 造船 | H31: =IFERROR(INDEX(词典!$G$2:$G$115,MATCH(G31,词典!$A$2:$A$115,0)),"") -> 赶上风口 | I31: =IFERROR(INDEX(词典!$H$2:$H$115,MATCH(G31,词典!$A$2:$A$115,0)),"") -> Ride the next big wave
